Workbook

Sheet SizeData
A1: Item Code# | B1: Size
A2: 735192 | B2: 750ml
A3: 48015 | B3: 375ml
A4: 37302 | B4: 750ml
A5: 607904 | B5: 750ml
A6: 86692 | B6: 750ml
A7: 89184 | B7: 750ml
A8: 415315 | B8: 1.5L
A9: 35592 | B9: 750ml
A10: 65191 | B10: 50ml
A11: 89679 | B11: 750ml
A12: 38064 | B12: 375ml
A13: 975002 | B13: 750ml
... A3811: 88241 | B3811: 100ml
A3812: 729099 | B3812: 187ml
A3813: 729077 | B3813: 187ml
A3814: 729021 | B3814: 187ml
A3815: 803475 | B3815: 187ml
A3816: 86751 | B3816: 750ml
A3817: 59536 | B3817: 750ml
A3818: 59551 | B3818: 750ml
A3819: 88291 | B3819: 50ml
A3820: 28281 | B3820: 1.75L
A3821: 729099 | B3821: 187ml
A3822: 88189 | B3822: 375ml
A3823: 10776 | B3823: 375ml
A3824: 26707 | B3824: 750ml
A3825: 425540 | B3825: 187ml
A3826: 884912 | B3826: 750ml
A3827: 884914 | B3827: 750ml
A3828: 26966 | B3828: 750ml
... A3839: 11588 | B3839: 1.75L

Sheet Warehouse
B1: =TODAY() | D1: =SUM(D2:D6219)
B2: Name | C2: Size | D2: Reserved Quantity | E2: Order | F2: Date | G2: Note
A3: 34008 | B3: ABSOLUT 80 VODKA | C3: =VLOOKUP(A3,SizeData!A$2:B$3839,2,FALSE) | D3: 4 | E3: R2084427 | F3: 45050
A4: 768681 | B4: ANDRE CHAMPAGNE PEACH MOSCATO | C4: =VLOOKUP(A4,SizeData!A$2:B$3839,2,FALSE) | D4: 4 | E4: R2084427 | F4: 45050
A5: 741200 | B5: ANDRE EXTRA DRY CHAMPAGNE | C5: =VLOOKUP(A5,SizeData!A$2:B$3839,2,FALSE) | D5: 4 | E5: R2079568 | F5: 45051
A6: 47548 | B6: ANSAC V S COGNAC | C6: =VLOOKUP(A6,SizeData!A$2:B$3839,2,FALSE) | D6: 2 | E6: R2088606 | F6: 45050
A7: 35083 | B7: ARISTOCRAT SUPREME VODKA | C7: =VLOOKUP(A7,SizeData!A$2:B$3839,2,FALSE) | D7: 1 | E7: R2079568 | F7: 45051
A8: 442562 | B8: BAREFOOT CELLARS RED MOSCATO CALIFORNIA | C8: =VLOOKUP(A8,SizeData!A$2:B$3839,2,FALSE) | D8: 1 | E8: R2079568 | F8: 45051
A9: 544109 | B9: BAREFOOT MOSCATO CALLIFORNIA | C9: =VLOOKUP(A9,SizeData!A$2:B$3839,2,FALSE) | D9: 1 | E9: R2079568 | F9: 45051
A10: 11788 | B10: BLACK VELVET | C10: =VLOOKUP(A10,SizeData!A$2:B$3839,2,FALSE) | D10: 1 | E10: R2084427 | F10: 45050
A11: 352440 | B11: BRICCO RIELLA MOSCATO D'ASTI | C11: =VLOOKUP(A11,SizeData!A$2:B$3839,2,FALSE) | D11: 2 | E11: R2086695 | F11: 45051
A12: 643820 | B12: BULLY HILL SWEET WALTER ROSE | C12: =VLOOKUP(A12,SizeData!A$2:B$3839,2,FALSE) | D12: 1 | E12: R2086695 | F12: 45051
A13: 35410 | B13: BURNETT'S 80 PROOF VODKA (PET) | C13: =VLOOKUP(A13,SizeData!A$2:B$3839,2,FALSE) | D13: 2 | E13: R2084427 | F13: 45050
A14: 12880 | B14: CANADIAN RICH & RARE (PET) | C14: =VLOOKUP(A14,SizeData!A$2:B$3839,2,FALSE) | D14: 3 | E14: R2084427 | F14: 45050
... A41: 498123 | B41: WOODBRIDGE BY ROBERT MONDAVI PINOT NOIR | C41: =VLOOKUP(A41,SizeData!A$2:B$3839,2,FALSE) | D41: 3 | E41: R2086695 | F41: 45051

Sheet  Pending Current
B1: =TODAY() | C1: Total | D1: =SUM(D3:D97257)
A2: Item # | B2: Name | C2: Size | D2: Reserved Quantity | E2: Order | F2: Date | G2: Notes
A3: 21236 | B3: 1792 SMALL BATCH BOURBON | C3: =VLOOKUP(A3,SizeData!A$2:B$3839,2,FALSE) | D3: 1 | E3: R2100722 | F3: 45054
A4: 64933 | B4: 1800 COCONUT FLAVORED TEQUILA | C4: =VLOOKUP(A4,SizeData!A$2:B$3839,2,FALSE) | D4: 4 | E4: R2087639 | F4: 45052
A5: 64932 | B5: 1800 COCONUT FLAVORED TEQUILA | C5: =VLOOKUP(A5,SizeData!A$2:B$3839,2,FALSE) | D5: 2 | E5: R2110019 | F5: 45057
A6: 89206 | B6: 1800 REPOSADO TEQUILA | C6: =VLOOKUP(A6,SizeData!A$2:B$3839,2,FALSE) | D6: 5 | E6: R2096156 | F6: 45055
A7: 87510 | B7: 1800 SILVER TEQUILA | C7: =VLOOKUP(A7,SizeData!A$2:B$3839,2,FALSE) | D7: 5 | E7: R2096156 | F7: 45055
A8: 84191 | B8: 99 BRAND BUTTERSCOTCH SCHNAPPS | C8: =VLOOKUP(A8,SizeData!A$2:B$3839,2,FALSE) | D8: 1 | E8: R2088667 | F8: 45058
A9: 84142 | B9: 99 BRAND PEACHES | C9: =VLOOKUP(A9,SizeData!A$2:B$3839,2,FALSE) | D9: 1 | E9: R2088667 | F9: 45058
A10: 87054 | B10: 99 BRAND PEANUT BUTTER WHISKEY | C10: =VLOOKUP(A10,SizeData!A$2:B$3839,2,FALSE) | D10: 1 | E10: R2088667 | F10: 45058
A11: 34003 | B11: ABSOLUT 80 VODKA | C11: =VLOOKUP(A11,SizeData!A$2:B$3839,2,FALSE) | D11: 1 | E11: R2098252 | F11: 45064
A12: 87027 | B12: ADICTIVO REPOSADO TEQUILA | C12: =VLOOKUP(A12,SizeData!A$2:B$3839,2,FALSE) | D12: 1 | E12: R2098904 | F12: 45056
A13: 741400 | B13: ANDRE CHAMPAGNE BRUT | C13: =VLOOKUP(A13,SizeData!A$2:B$3839,2,FALSE) | D13: 2 | E13: R2106288 | F13: 45059
A14: 768681 | B14: ANDRE CHAMPAGNE PEACH MOSCATO | C14: =VLOOKUP(A14,SizeData!A$2:B$3839,2,FALSE) | D14: 3 | E14: R2106288 | F14: 45059
... A245: 485433 | B245: MENAGE A TROIS HOT PINK SWEET ROSE COLLC | C245: =VLOOKUP(A245,SizeData!A$2:B$3839,2,FALSE) | D245: 1 | E245: R2121304 | F245: 45066

Sheet 2023
B1: =TODAY() | D1: =SUM(D2:D9997)
B2: Name | C2: Size | D2: Reserved Quantity | E2: Order | F2: Date | G2: Note
A3: 21236 | B3: 1792 SMALL BATCH BOURBON | C3: =VLOOKUP(A3,SizeData!A$2:B$3839,2,FALSE) | D3: 1 | E3: R1907721 | F3: 44908
A4: 21236 | B4: 1792 SMALL BATCH BOURBON | C4: =VLOOKUP(A4,SizeData!A$2:B$3839,2,FALSE) | D4: 1 | E4: R1939323 | F4: 44944
A5: 21236 | B5: 1792 SMALL BATCH BOURBON | C5: =VLOOKUP(A5,SizeData!A$2:B$3839,2,FALSE) | D5: 1 | E5: R1985201 | F5: 44963
A6: 21236 | B6: 1792 SMALL BATCH BOURBON | C6: =VLOOKUP(A6,SizeData!A$2:B$3839,2,FALSE) | D6: 1 | E6: R1998383 | F6: 44991
A7: 64933 | B7: 1800 COCONUT FLAVORED TEQUILA | C7: =VLOOKUP(A7,SizeData!A$2:B$3839,2,FALSE) | D7: 1 | E7: R1911462 | F7: 44917
A8: 64932 | B8: 1800 COCONUT FLAVORED TEQUILA | C8: =VLOOKUP(A8,SizeData!A$2:B$3839,2,FALSE) | D8: 1 | E8: R2062305 | F8: 45024
A9: 89204 | B9: 1800 REPOSADO TEQUILA | C9: =VLOOKUP(A9,SizeData!A$2:B$3839,2,FALSE) | D9: 1 | E9: R2016308 | F9: 44987
A10: 89206 | B10: 1800 REPOSADO TEQUILA | C10: =VLOOKUP(A10,SizeData!A$2:B$3839,2,FALSE) | D10: 1 | E10: R2020736 | F10: 44998
A11: 89208 | B11: 1800 REPOSADO TEQUILA | C11: =VLOOKUP(A11,SizeData!A$2:B$3839,2,FALSE) | D11: 3 | E11: R2051950 | F11: 45027
A12: 87564 | B12: 1800 SILVER | C12: =VLOOKUP(A12,SizeData!A$2:B$3839,2,FALSE) | D12: 3 | E12: R1951380 | F12: 44953
A13: 87564 | B13: 1800 SILVER | C13: =VLOOKUP(A13,SizeData!A$2:B$3839,2,FALSE) | D13: 2 | E13: R1961502 | F13: 44953
A14: 59185 | B14: 1800 ULTIMATE BLOOD ORANGE MARGARITA PET | C14: =VLOOKUP(A14,SizeData!A$2:B$3839,2,FALSE) | D14: 1 | E14: R1903667 | F14: 44915
... A97: 720850 | B97: ASTORIA SPARKLING MOSCATO | C97: =VLOOKUP(A97,SizeData!A$2:B$3839,2,FALSE) | D97: 2 | E97: R1911923 | F97: 44912
A98: 43124 | B98: Bacardi | C98: =VLOOKUP(A98,SizeData!A$2:B$3839,2,FALSE) | D98: 1
A99: 43034 | B99: BACARDI GOLD DARK RUM | C99: =VLOOKUP(A99,SizeData!A$2:B$3839,2,FALSE) | D99: 2 | E99: R1916440 | F99: 44916
A100: 82211 | B100: ARISTOCRAT PEACH SCHNAPPS | C100: =VLOOKUP(A100,SizeData!A$2:B$3839,2,FALSE) | D100: 1 | E100: R1972521 | F100: 44964
A101: 82211 | B101: ARISTOCRAT PEACH SCHNAPPS | C101: =VLOOKUP(A101,SizeData!A$2:B$3839,2,FALSE) | D101: 2 | E101: R2051950 | F101: 45027
A102: 35083 | B102: ARISTOCRAT SUPREME VODKA | C102: =VLOOKUP(A102,SizeData!A$2:B$3839,2,FALSE) | D102: 1 | E102: R1970895 | F102: 44961
A103: 35084 | B103: ARISTOCRAT SUPREME VODKA | C103: =VLOOKUP(A103,SizeData!A$2:B$3839,2,FALSE) | D103: 2 | E103: R1970895 | F103: 44961
A104: 35088 | B104: ARISTOCRAT SUPREME VODKA | C104: =VLOOKUP(A104,SizeData!A$2:B$3839,2,FALSE) | D104: 3 | E104: R1971458 | F104: 44961
A105: 43040 | B105: BACARDI GOLD DARK RUM (PET) | C105: =VLOOKUP(A105,SizeData!A$2:B$3839,2,FALSE) | D105: 4 | E105: R1916440 | F105: 44916
A106: 35088 | B106: ARISTOCRAT SUPREME VODKA | C106: =VLOOKUP(A106,SizeData!A$2:B$3839,2,FALSE) | D106: 1 | E106: R1992599 | F106: 44989
A107: 35084 | B107: ARISTOCRAT SUPREME VODKA | C107: =VLOOKUP(A107,SizeData!A$2:B$3839,2,FALSE) | D107: 1 | E107: R2062305 | F107: 45024
A108: 35084 | B108: ARISTOCRAT SUPREME VODKA | C108: =VLOOKUP(A108,SizeData!A$2:B$3839,2,FALSE) | D108: 1 | E108: R2056672 | F108: 45031
A109: 35083 | B109: ARISTOCRAT SUPREME VODKA | C109: =VLOOKUP(A109,SizeData!A$2:B$3839,2,FALSE) | D109: 1 | E109: R2073309 | F109: 45038
A110: 35088 | B110: ARISTOCRAT SUPREME VODKA | C110: =VLOOKUP(A110,SizeData!A$2:B$3839,2,FALSE) | D110: 2 | E110: R2082982 | F110: 45048
... A126: 43126 | B126: BACARDI LIGHT RUM | C126: =VLOOKUP(A126,SizeData!A$2:B$3839,2,FALSE) | D126: 1 | E126: R1949716 | F126: 44950
A127: 442562 | B127: BAREFOOT CELLARS RED MOSCATO CALIFORNIA | C127: =VLOOKUP(A127,SizeData!A$2:B$3839,2,FALSE) | D127: 2
A128: 43128 | B128: BACARDI LIGHT RUM | C128: =VLOOKUP(A128,SizeData!A$2:B$3839,2,FALSE) | D128: 1 | E128: R1957712 | F128: 44958
A129: 544110 | B129: BAREFOOT MOSCATO CALIFORNIA | C129: =VLOOKUP(A129,SizeData!A$2:B$3839,2,FALSE) | D129: 1 | E129: R1911923 | F129: 44912
A130: 43128 | B130: BACARDI LIGHT RUM | C130: =VLOOKUP(A130,SizeData!A$2:B$3839,2,FALSE) | D130: 2 | E130: R1985947 | F130: 44971
A131: 43128 | B131: BACARDI LIGHT RUM | C131: =VLOOKUP(A131,SizeData!A$2:B$3839,2,FALSE) | D131: 3 | E131: R1973788 | F131: 44972
A132: 43126 | B132: BACARDI LIGHT RUM | C132: =VLOOKUP(A132,SizeData!A$2:B$3839,2,FALSE) | D132: 5 | E132: R1992338 | F132: 44980
A133: 43124 | B133: BACARDI LIGHT RUM | C133: =VLOOKUP(A133,SizeData!A$2:B$3839,2,FALSE) | D133: 1 | E133: R2019856 | F133: 45005
A134: 43126 | B134: BACARDI LIGHT RUM | C134: =VLOOKUP(A134,SizeData!A$2:B$3839,2,FALSE) | D134: 3 | E134: R2083969 | F134: 45049
A135: 43136 | B135: BACARDI LIMON RUM SPECIALTY | C135: =VLOOKUP(A135,SizeData!A$2:B$3839,2,FALSE) | D135: 1 | E135: R1978112 | F135: 44972
A136: 768955 | B136: BALLATORE MOSCATO ROSE SPARKLING | C136: =VLOOKUP(A136,SizeData!A$2:B$3839,2,FALSE) | D136: 1 | E136: R1984929 | F136: 44980
A137: 642112 | B137: BAREFOOT PINK MOSCATO CALIFORNIA | C137: =VLOOKUP(A137,SizeData!A$2:B$3839,2,FALSE) | D137: 2 | E137: R1927120 | F137: 44924
...

Sheet Bulk
D1: =SUM(D3:D475)
A2: Item # | B2: Name | C2: Size | D2: Reserved Quantity | E2: Order | F2: Date | G2: Note
A4: 48105 | B4: HENNESSY V S COGNAC | C4: =VLOOKUP(A4,SizeData!A$2:B$3839,2,FALSE) | D4: 100 | E4: R2101701 | F4: 45056
A5: 48105 | B5: HENNESSY V S COGNAC | C5: =VLOOKUP(A5,SizeData!A$2:B$3839,2,FALSE) | D5: 40 | E5: R2100821 | F5: 45056
A6: 429955 | B6: YELLOW TAIL CHARDONNAY SOUTH EASTERN AUST | C6: =VLOOKUP(A6,SizeData!A$2:B$3839,2,FALSE) | D6: 15 | E6: R2087862 | F6: 45051
A7: hello

Sheet Cancelled
A2: Item # | B2: Name | C2: Size | D2: Reserved Quantity | E2: Order | F2: Date | G2: Notes
A3: 48099 | B3: HENNESSY V S COGNAC | C3: =VLOOKUP(A3,SizeData!A$2:B$3839,2,FALSE) | D3: 9 | E3: R1834724 | F3: 44860
A4: 4725 | B4: CHIVAS REGAL (ROUND) | C4: =VLOOKUP(A4,SizeData!A$2:B$3839,2,FALSE) | D4: 2 | E4: R1837345 | F4: 44859
A5: 87725 | B5: GRAN CORAMINO CRISTALINO REPOSADO TEQUILA LTO | C5: =VLOOKUP(A5,SizeData!A$2:B$3839,2,FALSE) | D5: 5 | E5: R1850607 | F5: 44860
A6: 44486 | B6: CRUZAN ESTATE DARK RUM | C6: =VLOOKUP(A6,SizeData!A$2:B$3839,2,FALSE) | D6: 1 | E6: R1816996 | F6: 44859
A7: 43533 | B7: PLANTATION O.F.T.D OVERPROOF DARK RUM | C7: =VLOOKUP(A7,SizeData!A$2:B$3839,2,FALSE) | D7: 1 | E7: R1829977 | F7: 44861
A8: 552052 | B8: CARLO ROSSI CHARDONNAY | C8: =VLOOKUP(A8,SizeData!A$2:B$3839,2,FALSE) | D8: 1 | E8: R1829977 | F8: 44861
A9: 683326 | B9: SUTTER HOME PINK MOSCATO CALIFORNIA | C9: =VLOOKUP(A9,SizeData!A$2:B$3839,2,FALSE) | D9: 3 | E9: R1834547 | F9: 44861
A10: 5555 | B10: THE MACALLAN DOUBLE CASK 12Y HIGHLAND SINGLE MALT | C10: =VLOOKUP(A10,SizeData!A$2:B$3839,2,FALSE) | D10: 2 | E10: R1841287 | F10: 44861
A11: 44516 | B11: CRUZAN ESTATE LIGHT RUM | C11: =VLOOKUP(A11,SizeData!A$2:B$3839,2,FALSE) | D11: 2 | E11: R1834591 | F11: 44863
A12: 49376 | B12: SALIGNAC V S | C12: =VLOOKUP(A12,SizeData!A$2:B$3839,2,FALSE) | D12: 1 | E12: R1834591 | F12: 44863
A13: 51109 | B13: CIROC VS FRENCH BRANDY | C13: =VLOOKUP(A13,SizeData!A$2:B$3839,2,FALSE) | D13: 2 | E13: R1834591 | F13: 44863
A14: 87484 | B14: DON JULIO SILVER TEQUILA WHITE | C14: =VLOOKUP(A14,SizeData!A$2:B$3839,2,FALSE) | D14: 2 | E14: R1840965 | F14: 44863
... A409: 86851 | B409: OLE SMOKEY BLUE FLAME TENNESSEE MOONSHINE | C409: =VLOOKUP(A409,SizeData!A$2:B$3839,2,FALSE) | D409: 2 | E409: R2083415 | F409: 45048

Sheet 2022
D1: Total | F1: =SUM(D4:D8751)
A3: Item # | B3: Name | C3: Size | D3: Reserved Quantity | E3: Order | F3: Date | G3: Note | J3: Taaka 100 ml - 252 on Oct 1st | M3: Martell 375ml - 325 on Oct 6th | Q3: 42 HENNESSY 750ML ON 11/17/2022 FROM 36.99 SALE
A4: 302850 | B4: "DR" LOOSEN RIESLING "DR. L" | C4: =VLOOKUP(A4,SizeData!A$2:B$3839,2,FALSE) | D4: 1 | E4: R1761638 | F4: 44807
A5: 21236 | B5: 1792 SMALL BATCH BOURBON | C5: =VLOOKUP(A5,SizeData!A$2:B$3839,2,FALSE) | D5: 1 | E5: R1376605 | F5: 44544
A6: 21236 | B6: 1792 SMALL BATCH BOURBON | C6: =VLOOKUP(A6,SizeData!A$2:B$3839,2,FALSE) | D6: 1 | E6: R1413566 | F6: 44580
A7: 21236 | B7: 1792 SMALL BATCH BOURBON | C7: =VLOOKUP(A7,SizeData!A$2:B$3839,2,FALSE) | D7: 1 | E7: R1471479 | F7: 44614
A8: 21236 | B8: 1792 SMALL BATCH BOURBON | C8: =VLOOKUP(A8,SizeData!A$2:B$3839,2,FALSE) | D8: 1 | E8: R1512696 | F8: 44637
A9: 21236 | B9: 1792 SMALL BATCH BOURBON | C9: =VLOOKUP(A9,SizeData!A$2:B$3839,2,FALSE) | D9: 1 | E9: R1568544 | F9: 44669
A10: 21236 | B10: 1792 SMALL BATCH BOURBON | C10: =VLOOKUP(A10,SizeData!A$2:B$3839,2,FALSE) | D10: 1 | E10: R1624762 | F10: 44712
A11: 21236 | B11: 1792 SMALL BATCH BOURBON | C11: =VLOOKUP(A11,SizeData!A$2:B$3839,2,FALSE) | D11: 1 | E11: R1809877 | F11: 44851
A12: 59192 | B12: 1800 BLACK CHERRY ULTIMATE MARGARITA | C12: =VLOOKUP(A12,SizeData!A$2:B$3839,2,FALSE) | D12: 2 | E12: R1383976 | F12: 44561
A13: 59192 | B13: 1800 BLACK CHERRY ULTIMATE MARGARITA | C13: =VLOOKUP(A13,SizeData!A$2:B$3839,2,FALSE) | D13: 3 | E13: R1529670 | F13: 44652
A14: 59192 | B14: 1800 BLACK CHERRY ULTIMATE MARGARITA | C14: =VLOOKUP(A14,SizeData!A$2:B$3839,2,FALSE) | D14: 2 | E14: R1583381 | F14: 44679
A15: 59192 | B15: 1800 BLACK CHERRY ULTIMATE MARGARITA | C15: =VLOOKUP(A15,SizeData!A$2:B$3839,2,FALSE) | D15: 1 | E15: R1671975 | F15: 44742
... A670: 35417 | B670: BURNETT'S VODKA 80 PROOF | C670: =VLOOKUP(A670,SizeData!A$2:B$3839,2,FALSE) | D670: 4 | E670: R1660776 | F670: 44733
A671: 35417 | B671: BURNETT'S VODKA 80 PROOF | C671: =VLOOKUP(A671,SizeData!A$2:B$3839,2,FALSE) | D671: 12 | E671: R1766206 | F671: 44806 | G671: Weekly Average 2.3
A672: 35417 | B672: BURNETT'S VODKA 80 PROOF | C672: =VLOOKUP(A672,SizeData!A$2:B$3839,2,FALSE) | D672: 5 | E672: R1777984 | F672: 44826
A673: 35417 | B673: BURNETT'S VODKA 80 PROOF | C673: =VLOOKUP(A673,SizeData!A$2:B$3839,2,FALSE) | D673: 2 | E673: R1796778 | F673: 44834
A674: 35417 | B674: BURNETT'S VODKA 80 PROOF | C674: =VLOOKUP(A674,SizeData!A$2:B$3839,2,FALSE) | D674: 5 | E674: R1900430 | F674: 44896
A675: 35417 | B675: BURNETT'S VODKA 80 PROOF | C675: =VLOOKUP(A675,SizeData!A$2:B$3839,2,FALSE) | D675: 5 | E675: R1906202 | F675: 44902
A676: 35418 | B676: BURNETT'S VODKA 80 PROOF | C676: =VLOOKUP(A676,SizeData!A$2:B$3839,2,FALSE) | D676: 5 | E676: R1630969 | F676: 44711
A677: 35418 | B677: BURNETT'S VODKA 80 PROOF | C677: =VLOOKUP(A677,SizeData!A$2:B$3839,2,FALSE) | D677: 8 | E677: R1713939 | F677: 44779
A678: 35418 | B678: BURNETT'S VODKA 80 PROOF | C678: =VLOOKUP(A678,SizeData!A$2:B$3839,2,FALSE) | D678: 5 | E678: R1756377 | F678: 44804
A679: 35418 | B679: BURNETT'S VODKA 80 PROOF | C679: =VLOOKUP(A679,SizeData!A$2:B$3839,2,FALSE) | D679: 20 | E679: R1856308 | F679: 44867
A680: 35418 | B680: BURNETT'S VODKA 80 PROOF | C680: =VLOOKUP(A680,SizeData!A$2:B$3839,2,FALSE) | D680: 4 | E680: R1881344 | F680: 44893
A681: 35418 | B681: BURNETT'S VODKA 80 PROOF | C681: =VLOOKUP(A681,SizeData!A$2:B$3839,2,FALSE) | D681: 5 | E681: R1891609 | F681: 44895
A682: 35418 | B682: BURNETT'S VODKA 80 PROOF | C682: =VLOOKUP(A682,SizeData!A$2:B$3839,2,FALSE) | D682: 1 | E682: R1881344 | F682: 44893
A683: 42031 | B683: BURNETT'S WHIPPED CREAM FLAVORED VODKA | C683: =VLOOKUP(A683,SizeData!A$2:B$3839,2,FALSE) | D683: 2 | E683: R1436614 | F683: 44586
... A1313: 744200 | B1313: COOK'S BRUT CHAMPAGNE | C1313: =VLOOKUP(A1313,SizeData!A$2:B$3839,2,FALSE) | D1313: 2 | E1313: R1696453 | F1313: 44758
A1314: 744200 | B1314: COOK'S BRUT CHAMPAGNE | C1314: =VLOOKUP(A1314,SizeData!A$2:B$3839,2,FALSE) | D1314: 20 | E1314: 1059.6 | F1314: 44760
A1315: 744200 | B1315: COOK'S BRUT CHAMPAGNE | C1315: =VLOOKUP(A1315,SizeData!A$2:B$3839,2,FALSE) | D1315: 5 | E1315: R1684665 | F1315: 44765
A1316: 744205 | B1316: COOK'S BRUT CHAMPAGNE | C1316: =VLOOKUP(A1316,SizeData!A$2:B$3839,2,FALSE) | D1316: 5 | E1316: R1681159 | F1316: 44757
A1317: 744205 | B1317: COOK'S BRUT CHAMPAGNE | C1317: =VLOOKUP(A1317,SizeData!A$2:B$3839,2,FALSE) | D1317: 10 | E1317: R1695784 | F1317: 44760
A1318: 744205 | B1318: COOK'S BRUT CHAMPAGNE | C1318: =VLOOKUP(A1318,SizeData!A$2:B$3839,2,FALSE) | D1318: 8 | E1318: R1702988 | F1318: 44771
A1319: 744400 | B1319: COOK'S EXTRA DRY CHAMPAGNE | C1319: =VLOOKUP(A1319,SizeData!A$2:B$3839,2,FALSE) | D1319: 3 | E1319: R1681159 | F1319: 44757
A1320: 744400 | B1320: COOK'S EXTRA DRY CHAMPAGNE | C1320: =VLOOKUP(A1320,SizeData!A$2:B$3839,2,FALSE) | D1320: 10 | E1320: R1695784 | F1320: 44760
A1321: 744405 | B1321: COOK'S EXTRA DRY CHAMPAGNE | C1321: =VLOOKUP(A1321,SizeData!A$2:B$3839,2,FALSE) | D1321: 1 | E1321: R1572421 | F1321: 44667
A1322: 744405 | B1322: COOK'S EXTRA DRY CHAMPAGNE | C1322: =VLOOKUP(A1322,SizeData!A$2:B$3839,2,FALSE) | D1322: 1 | E1322: R1604328 | F1322: 44694
A1323: 744405 | B1323: COOK'S EXTRA DRY CHAMPAGNE | C1323: =VLOOKUP(A1323,SizeData!A$2:B$3839,2,FALSE) | D1323: 1 | E1323: R1679342 | F1323: 44753
A1324: 769925 | B1324: COOK'S SPUMANTE | C1324: =VLOOKUP(A1324,SizeData!A$2:B$3839,2,FALSE) | D1324: 1 | E1324: R1512696 | F1324: 44637
...

Sheet 2021
D1: Total | F1: =SUM(D4:D8998)
A3: Item # | B3: Name | C3: Size | D3: Reserved Quantity | E3: Order | F3: Date | G3: Note
A4: 447 | B4: KNOB CREEK GLASS HOLIDAY GIFT | C4: =VLOOKUP(A4,SizeData!A$2:B$3839,2,FALSE) | D4: 3 | E4: R1283220 | F4: 44483
A5: 464 | B5: GN ORIGINAL 6 750ML(VAP) | C5: =VLOOKUP(A5,SizeData!A$2:B$3839,2,FALSE) | D5: 2 | E5: R1337036A | F5: 44541
A6: 1400 | B6: CROWN ROYAL W/2 STATE GLASSES | C6: =VLOOKUP(A6,SizeData!A$2:B$3839,2,FALSE) | D6: 10 | E6: R1305412 | F6: 44488
A7: 1400 | B7: CROWN ROYAL W/2 STATE GLASSES | C7: =VLOOKUP(A7,SizeData!A$2:B$3839,2,FALSE) | D7: 10 | E7: R1297436 | F7: 44494
A8: 4000 | B8: ABERFELDY 12 YR SINGLE MALT | C8: =VLOOKUP(A8,SizeData!A$2:B$3839,2,FALSE) | D8: 1 | E8: R1122623 | F8: 44331
A9: 4000 | B9: ABERFELDY 12 YR SINGLE MALT | C9: =VLOOKUP(A9,SizeData!A$2:B$3839,2,FALSE) | D9: 1 | E9: R1146432 | F9: 44356
A10: 4000 | B10: ABERFELDY 12 YR SINGLE MALT | C10: =VLOOKUP(A10,SizeData!A$2:B$3839,2,FALSE) | D10: 1 | E10: R1175279 | F10: 44382
A11: 4616 | B11: BUCHANANS 18YR OLD SPECIAL RESERVE | C11: =VLOOKUP(A11,SizeData!A$2:B$3839,2,FALSE) | D11: 1 | E11: R998330 | F11: 44207
A12: 4616 | B12: BUCHANANS 18YR OLD SPECIAL RESERVE | C12: =VLOOKUP(A12,SizeData!A$2:B$3839,2,FALSE) | D12: 1 | E12: R1094301 | F12: 44301
A13: 4616 | B13: BUCHANANS 18YR OLD SPECIAL RESERVE | C13: =VLOOKUP(A13,SizeData!A$2:B$3839,2,FALSE) | D13: 0 | E13: R1236687 | F13: 44448
A14: 4616 | B14: BUCHANANS 18YR OLD SPECIAL RESERVE | C14: =VLOOKUP(A14,SizeData!A$2:B$3839,2,FALSE) | D14: 2 | E14: R1337698 | F14: 44531
A15: 4626 | B15: BUCHANAN DELUXE 12YR SCOTCH | C15: =VLOOKUP(A15,SizeData!A$2:B$3839,2,FALSE) | D15: 4 | E15: R998330 | F15: 44207
... A353: 17958 | B353: EVAN WILLIAMS BLACK | C353: =VLOOKUP(A353,SizeData!A$2:B$3839,2,FALSE) | D353: 1 | E353: R1072840 | F353: 44286
A354: 17958 | B354: EVAN WILLIAMS BLACK | C354: =VLOOKUP(A354,SizeData!A$2:B$3839,2,FALSE) | D354: 4 | E354: R1228454 | F354: 44445 | G354: Out of 8
A355: 17958 | B355: EVAN WILLIAMS BLACK | C355: =VLOOKUP(A355,SizeData!A$2:B$3839,2,FALSE) | D355: 4 | E355: R1253502 | F355: 44460
A356: 18116 | B356: EVAN WILLIAMS BLACK PET | C356: =VLOOKUP(A356,SizeData!A$2:B$3839,2,FALSE) | D356: 1 | E356: R1346277 | F356: 44530
A357: 18196 | B357: EZRA BROOKS | C357: =VLOOKUP(A357,SizeData!A$2:B$3839,2,FALSE) | D357: 1 | E357: R1273155 | F357: 44480
A358: 18348 | B358: FOUR ROSES SMALL BATCH BOURBON | C358: =VLOOKUP(A358,SizeData!A$2:B$3839,2,FALSE) | D358: 1 | E358: R1066328 | F358: 44267
A359: 18351 | B359: FOUR ROSES BOURBON YELLOW LABEL | C359: =VLOOKUP(A359,SizeData!A$2:B$3839,2,FALSE) | D359: 1 | E359: R1154324 | F359: 44378
A360: 18351 | B360: FOUR ROSES BOURBON YELLOW LABEL | C360: =VLOOKUP(A360,SizeData!A$2:B$3839,2,FALSE) | D360: 2 | E360: R1170994 | F360: 44394
A361: 18352 | B361: FOUR ROSES BOURBON YELLOW LABEL | C361: =VLOOKUP(A361,SizeData!A$2:B$3839,2,FALSE) | D361: 1 | E361: R1106414 | F361: 44307
A362: 18352 | B362: FOUR ROSES BOURBON YELLOW LABEL | C362: =VLOOKUP(A362,SizeData!A$2:B$3839,2,FALSE) | D362: 1 | E362: R1099557 | F362: 44317
A363: 18352 | B363: FOUR ROSES BOURBON YELLOW LABEL | C363: =VLOOKUP(A363,SizeData!A$2:B$3839,2,FALSE) | D363: 2 | E363: R1200565 | F363: 44411
A364: 18352 | B364: FOUR ROSES BOURBON YELLOW LABEL | C364: =VLOOKUP(A364,SizeData!A$2:B$3839,2,FALSE) | D364: 1 | E364: R1296060 | F364: 44491
A365: 18352 | B365: FOUR ROSES BOURBON YELLOW LABEL | C365: =VLOOKUP(A365,SizeData!A$2:B$3839,2,FALSE) | D365: 0 | E365: R1301983 | F365: 44501
A366: 18352 | B366: FOUR ROSES BOURBON YELLOW LABEL | C366: =VLOOKUP(A366,SizeData!A$2:B$3839,2,FALSE) | D366: 3 | E366: R1314326 | F366: 44512
... A529: 25608 | B529: SEAGRAM'S 7 CROWN BLENDED WHISKEY | C529: =VLOOKUP(A529,SizeData!A$2:B$3839,2,FALSE) | D529: 20 | E529: R1075059 | F529: 44273
A530: 25608 | B530: SEAGRAM'S 7 CROWN BLENDED WHISKEY | C530: =VLOOKUP(A530,SizeData!A$2:B$3839,2,FALSE) | D530: 20 | F530: 44277
A531: 25603 | B531: SEAGRAM'S 7 CROWN BLENDED WHISKEY | C531: =VLOOKUP(A531,SizeData!A$2:B$3839,2,FALSE) | D531: 5 | E531: R1015412 | F531: 44215
A532: 25603 | B532: SEAGRAM'S 7 CROWN BLENDED WHISKEY | C532: =VLOOKUP(A532,SizeData!A$2:B$3839,2,FALSE) | D532: 2 | E532: R1060153 | F532: 44264
A533: 25603 | B533: SEAGRAM'S 7 CROWN BLENDED WHISKEY | C533: =VLOOKUP(A533,SizeData!A$2:B$3839,2,FALSE) | D533: 5 | E533: R1173019 | F533: 44391
A534: 25603 | B534: SEAGRAM'S 7 CROWN BLENDED WHISKEY | C534: =VLOOKUP(A534,SizeData!A$2:B$3839,2,FALSE) | D534: 2 | E534: R1251315 | F534: 44454
A535: 25603 | B535: SEAGRAM'S 7 CROWN BLENDED WHISKEY | C535: =VLOOKUP(A535,SizeData!A$2:B$3839,2,FALSE) | D535: 4 | E535: R1306609 | F535: 44495
A536: 25603 | B536: SEAGRAM'S 7 CROWN BLENDED WHISKEY | C536: =VLOOKUP(A536,SizeData!A$2:B$3839,2,FALSE) | D536: 5 | E536: R1340649 | F536: 44523
A537: 25604 | B537: SEAGRAM'S 7 CROWN BLENDED WHISKEY | C537: =VLOOKUP(A537,SizeData!A$2:B$3839,2,FALSE) | D537: 10 | E537: R997415 | F537: 44203
A538: 25604 | B538: SEAGRAM'S 7 CROWN BLENDED WHISKEY | C538: =VLOOKUP(A538,SizeData!A$2:B$3839,2,FALSE) | D538: 10 | E538: R1010284 | F538: 44217
A539: 25604 | B539: SEAGRAM'S 7 CROWN BLENDED WHISKEY | C539: =VLOOKUP(A539,SizeData!A$2:B$3839,2,FALSE) | D539: 10 | E539: R1038155 | F539: 44257
A540: 25604 | B540: SEAGRAM'S 7 CROWN BLENDED WHISKEY | C540: =VLOOKUP(A540,SizeData!A$2:B$3839,2,FALSE) | D540: 10 | E540: R1057200 | F540: 44278
...

Sheet Pending
B1: =TODAY() | C1: Total | D1: =SUM(D3:D1049)
A2: Item # | B2: Name | C2: Size | D2: Reserved Quantity | E2: Order | F2: Date | G2: Notes
A3: 21236 | B3: 1792 SMALL BATCH BOURBON | C3: =VLOOKUP(A3,SizeData!A$2:B$3839,2,FALSE) | D3: 1 | E3: R1893307 | F3: 44898
A4: 64933 | B4: 1800 COCONUT FLAVORED TEQUILA | C4: =VLOOKUP(A4,SizeData!A$2:B$3839,2,FALSE) | D4: 2 | E4: R1892170 | F4: 44902
A5: 87513 | B5: 1800 SILVER TEQUILA | C5: =VLOOKUP(A5,SizeData!A$2:B$3839,2,FALSE) | D5: 10 | E5: R1868085 | F5: 44890
A6: 671421 | B6: 19 CRIMES CALI ROSE | C6: =VLOOKUP(A6,SizeData!A$2:B$3839,2,FALSE) | D6: 1 | E6: R1900430 | F6: 44896
A7: 490692 | B7: 19 CRIMES MODERN CALI RED | C7: =VLOOKUP(A7,SizeData!A$2:B$3839,2,FALSE) | D7: 1 | E7: R1900430 | F7: 44896
A8: 490692 | B8: 19 CRIMES MODERN CALI RED | C8: =VLOOKUP(A8,SizeData!A$2:B$3839,2,FALSE) | D8: 2 | E8: R1890841 | F8: 44898
A9: 419952 | B9: 19 CRIMES RED WINE | C9: =VLOOKUP(A9,SizeData!A$2:B$3839,2,FALSE) | D9: 1 | E9: R1900430 | F9: 44896
A10: 419961 | B10: 19 CRIMES THE UPRISING RED WINE | C10: =VLOOKUP(A10,SizeData!A$2:B$3839,2,FALSE) | D10: 1 | E10: R1900430 | F10: 44896
A11: 419961 | B11: 19 CRIMES THE UPRISING RED WINE | C11: =VLOOKUP(A11,SizeData!A$2:B$3839,2,FALSE) | D11: 2 | E11: R1890841 | F11: 44898
A12: 84142 | B12: 99 BRAND PEACHES | C12: =VLOOKUP(A12,SizeData!A$2:B$3839,2,FALSE) | D12: 1 | E12: R1877599 | F12: 44896
A13: 34003 | B13: ABSOLUT 80 VODKA | C13: =VLOOKUP(A13,SizeData!A$2:B$3839,2,FALSE) | D13: 1 | E13: R1880771 | F13: 44895
A14: 34007 | B14: ABSOLUT 80 VODKA | C14: =VLOOKUP(A14,SizeData!A$2:B$3839,2,FALSE) | D14: 2 | E14: R1883576 | F14: 44895
... A403: 429982 | B403: YELLOW TAIL RIESLING | C403: =VLOOKUP(A403,SizeData!A$2:B$3839,2,FALSE) | D403: 2 | E403: R1880771 | F403: 44895

Sheet Special Order 2022
A1: Retail Order Id | B1: Created | C1: Item Code | D1: Name | E1: Units | F1: Retailer Case Cost | G1: Quantity | H1: Requested | I1: Reserved | J1: Filled | K1: Order Status | L1: Broker Name
A2: R1479383 | B2: 44617 | C2: 87508 | D2: 1800 SILVER TEQUILA | E2: 60 | F2: 124.9 | G2: 2 | H2: 2 | I2: 2 | J2: 2 | K2: Shipped | L2: RNDC-MAGNOLIA
A3: R1701939A | B3: 44776 | C3: 33757 | D3: ABSOLUT ELYX | E3: 6 | F3: 126.82 | G3: 1 | H3: 1 | I3: 1 | J3: 1 | K3: Shipped | L3: SOUTHERN GLAZER'S WINE AND SPIRITS OF MISSISSIPPI LLC
A4: R1701939A | B4: 44776 | C4: 36768 | D4: ABSOLUT GRAPEFRUIT FLAVORED VODKA | E4: 24 | F4: 122.07 | G4: 1 | H4: 1 | I4: 1 | J4: 1 | K4: Shipped | L4: SOUTHERN GLAZER'S WINE AND SPIRITS OF MISSISSIPPI LLC
A5: R1718636 | B5: 44777 | C5: 36685 | D5: ABSOLUT LIME FLAVORED VODKA | E5: 24 | F5: 122.07 | G5: 1 | H5: 1 | I5: 1 | J5: 1 | K5: Shipped | L5: SOUTHERN GLAZER'S WINE AND SPIRITS OF MISSISSIPPI LLC
A6: R1323780A | B6: 44600 | C6: 87033 | D6: ADICTIVO ANEJO TEQUILA | E6: 6 | F6: 299.96 | G6: 1 | H6: 1 | I6: 1 | J6: 1 | K6: Shipped | L6: RNDC-VINTAGE
A7: R1607323 | B7: 44690 | C7: 87031 | D7: ADICTIVO EXTRA ANEJO CRISTALINO TEQUILA | E7: 6 | F7: 485.57 | G7: 1 | H7: 1 | I7: 1 | J7: 1 | K7: Shipped | L7: RNDC-VINTAGE
A8: R1594555 | B8: 44694 | C8: 42082 | D8: ANGOSTURA 5 YEAR GOLD RUM TRINADAD | E8: 6 | F8: 111.67 | G8: 1 | H8: 1 | I8: 1 | J8: 1 | K8: Shipped | L8: SOUTHERN GLAZER'S WINE AND SPIRITS OF MISSISSIPPI LLC
A9: R1739999 | B9: 44799 | C9: 88827 | D9: AVION RESERVA 44 EXTRA ANEJO TEQUILA | E9: 4 | F9: 371.44 | G9: 1 | H9: 1 | I9: 1 | J9: 1 | K9: Shipped | L9: SOUTHERN GLAZER'S WINE AND SPIRITS OF MISSISSIPPI LLC
A10: R1595992 | B10: 44685 | C10: 87156 | D10: AVION RESERVA CRISTALINO | E10: 4 | F10: 462.5 | G10: 1 | H10: 1 | I10: 1 | J10: 1 | K10: Shipped | L10: SOUTHERN GLAZER'S WINE AND SPIRITS OF MISSISSIPPI LLC
A11: R1593524 | B11: 44683 | C11: 16659 | D11: BASIL HAYDEN SUBTLE SMOKE | E11: 6 | F11: 230.72 | G11: 1 | H11: 1 | I11: 1 | J11: 1 | K11: Shipped | L11: SOUTHERN GLAZER'S WINE AND SPIRITS OF MISSISSIPPI LLC
A12: R1411880 | B12: 44575 | C12: 16850 | D12: BLANTON SINGLE BARREL BOURBON | E12: 6 | F12: 277.88 | G12: 2 | H12: 2 | I12: 2 | J12: 2 | K12: Shipped | L12: RNDC-MAGNOLIA
A13: R1458823A | B13: 44615 | C13: 16850 | D13: BLANTON SINGLE BARREL BOURBON | E13: 6 | F13: 277.88 | G13: 1 | H13: 1 | I13: 1 | J13: 1 | K13: Shipped | L13: RNDC-MAGNOLIA
... A202: R1702727 | B202: 44767 | C202: 904346 | D202: WOODFORD RSV DBL OAKED PERSONAL SELECTION - JASCO | E202: 6 | F202: 308.41 | G202: 20 | H202: 20 | I202: 20 | J202: 20 | K202: Shipped | L202: UNITED JOHNSON BROTHERS OF MS
C203: 904347 | E203: 6853 | F203: 45654.83 | G203: 471 | H203: 471 | I203: 471 | J203: 463
C204: 904348
C205: 904349
C206: 904350
A207: 88738 | B207: TORADA WHITE TEQUILA | C207: 904351 | D207: 4 | E207: R1903748
A208: 89219 | B208: JOSE CUERVO TRADICIONAL REPOSADO | C208: 904352 | D208: 5 | E208: R1903748
A209: 89196 | B209: JOSE CUERVO ESPECIAL TEQUILA GOLD | C209: 904353 | D209: 5 | E209: R1903748
A210: 87402 | B210: JOSE CUERVO ESPECIAL SILVER | C210: 904354 | D210: 1 | E210: R1903748
A211: 84222 | B211: 99 BRAND BLUE RASPBERRIES | C211: 904355 | D211: 1 | E211: R1903748
A212: 84142 | B212: 99 BRAND PEACHES | C212: 904356 | D212: 1 | E212: R1903748
A213: 84172 | B213: 99 BRAND BANANAS SCHNAPPS | C213: 904357 | D213: 1 | E213: R1903748
A214: 49185 | B214: REMY MARTIN VSOP COGNAC (FLASK) | C214: 904358 | D214: 5 | E214: R1899553
A215: 49084 | B215: REMY MARTIN 1738 ACCORD ROYAL COGNAC | C215: 904359 | D215: 5 | E215: R1899553

Sheet All Products
B1: Item Code | C1: Name | D1: Size | E1: Available | F1: Reserved | G1: Units | H1: Case Cost | I1: Discount | J1: Split Bottle | K1: Bottle Cost | L1: Category | M1: Supplier Name | N1: Broker | O1: Availability Type | P1: SSCC Code | Q1: UPC Code | R1: Listing Date
A2: item code = | B2: 59854 | C2: HORNITOS STRAWBERRY TAMARIND MARGARITA | D2: 1.75L | E2: 18 | F2: 1 | G2: 6 | H2: 96.87 | I2: 0 | J2: False | K2: 0 | L2: COCKTAILS | M2: JIM BEAM BRANDS CO | N2: 040010-SOUTHERN GLAZERS WINE AND SPIRITS OF MISSISSIPPI LLC | P2: 10080686847028 | Q2: 080686847021 | R2: 44593
A3: or item code = | B3: 302850 | C3: "DR" LOOSEN RIESLING "DR. L" | D3: 750ml | E3: 104 | F3: 56 | G3: 12 | H3: 135.25 | I3: 0 | J3: False | K3: 0 | L3: RIESLING (WHITE/JOHANN) | M3: INTERNATIONAL WINES INC | N3: 040017-INTERNATIONAL WINES | P3: 00018310300001 | Q3: 0183103000013 | R3: 43525
A4: or item code = | B4: 21236 | C4: 1792 SMALL BATCH BOURBON | D4: 750ml | E4: 0 | F4: 4 | G4: 6 | H4: 143.04 | I4: 0 | J4: False | K4: 0 | L4: WHISKEY - STR BOURBON | M4: SAZERAC COMPANY | N4: 040010-SOUTHERN GLAZERS WINE AND SPIRITS OF MISSISSIPPI LLC | P4: 00881001000281 | Q4: 0080660001203 | R4: 42370
A5: or item code = | B5: 89230 | C5: 1800 ANEJO TEQUILA | D5: 750ml | E5: 32 | F5: 37 | G5: 6 | H5: 184.93 | I5: 0 | J5: False | K5: 0 | L5: TEQUILA | M5: PROXIMO SPIRITS INC | N5: 040002-RNDC-MAGNOLIA | P5: 10811538010037 | Q5: 811538010030 | R5: 44228
A6: or item code = | B6: 59192 | C6: 1800 BLACK CHERRY ULTIMATE MARGARITA PET | D6: 1.75L | E6: 0 | F6: 78 | G6: 6 | H6: 106.1 | I6: 0 | J6: False | K6: 0 | L6: TEQUILA | M6: PROXIMO SPIRITS INC | N6: 040002-RNDC-MAGNOLIA | P6: 10818844021412 | Q6: 818844021415 | R6: 44287
A7: or item code = | B7: 64932 | C7: 1800 COCONUT FLAVORED TEQUILA | D7: 375ml | E7: 57 | F7: 80 | G7: 12 | H7: 126.7 | I7: 0 | J7: False | K7: 0 | L7: TEQUILA | M7: PROXIMO SPIRITS INC | N7: 040002-RNDC-MAGNOLIA | P7: 20811538018115 | Q7: 0811538010368 | R7: 42370
A8: or item code = | B8: 64933 | C8: 1800 COCONUT FLAVORED TEQUILA | D8: 750ml | E8: 15 | F8: 21 | G8: 12 | H8: 273.7 | I8: 0 | J8: False | K8: 0 | L8: TEQUILA | M8: PROXIMO SPIRITS INC | N8: 040002-RNDC-MAGNOLIA | P8: 20811538010379 | Q8: 0811538010375 | R8: 42370
A9: or item code = | B9: 89206 | C9: 1800 REPOSADO TEQUILA | D9: 750ml | E9: 0 | F9: 0 | G9: 12 | H9: 282.82 | I9: 0 | J9: False | K9: 0 | L9: TEQUILA | M9: PROXIMO SPIRITS INC | N9: 040002-RNDC-MAGNOLIA | P9: 10818844022051 | Q9: 0811538010238 | R9: 42370
A10: or item code = | B10: 89204 | C10: 1800 REPOSADO TEQUILA | D10: 375ml | E10: 0 | F10: 4 | G10: 12 | H10: 130.92 | I10: 0 | J10: False | K10: 0 | L10: TEQUILA | M10: PROXIMO SPIRITS INC | N10: 040002-RNDC-MAGNOLIA | P10: 20811538019969 | Q10: 0811538010221 | R10: 42370
A11: or item code = | B11: 89208 | C11: 1800 REPOSADO TEQUILA | D11: 1.75L | E11: 1 | F11: 19 | G11: 6 | H11: 244.57 | I11: 0 | J11: False | K11: 0 | L11: TEQUILA | M11: PROXIMO SPIRITS INC | N11: 040002-RNDC-MAGNOLIA | P11: 10811538019993 | Q11: 0811538010252 | R11: 42370
A12: or item code = | B12: 87564 | C12: 1800 SILVER | D12: 100ml | E12: 0 | F12: 0 | G12: 48 | H12: 185.67 | I12: 0 | J12: False | K12: 0 | L12: TEQUILA | M12: PROXIMO SPIRITS INC | N12: 040002-RNDC-MAGNOLIA | P12: 30811538018242 | Q12: 811538018241 | R12: 44228
A13: or item code = | B13: 87513 | C13: 1800 SILVER TEQUILA | D13: 1.75L | E13: 170 | F13: 86 | G13: 6 | H13: 235.34 | I13: 0 | J13: False | K13: 0 | L13: TEQUILA | M13: PROXIMO SPIRITS INC | N13: 040002-RNDC-MAGNOLIA | P13: 10811538016855 | Q13: 811538010153 | R13: 42370
... A16: or item code = | B16: 87510 | C16: 1800 SILVER TEQUILA | D16: 750ml | E16: 0 | F16: 198 | G16: 12 | H16: 273.7 | I16: 0 | J16: False | K16: 0 | L16: TEQUILA | M16: PROXIMO SPIRITS INC | N16: 040002-RNDC-MAGNOLIA | P16: 20818844021938 | Q16: 0811538010139 | R16: 42370
A17: or item code = | B17: 59180 | C17: 1800 SPICY ULTIMATE MARGARITA | D17: 1.75L | E17: 39 | F17: 16 | G17: 6 | H17: 106.1 | I17: 0 | J17: False | K17: 0 | L17: COCKTAILS | M17: PROXIMO SPIRITS INC | N17: 040002-RNDC-MAGNOLIA | Q17: 811538014557 | R17: 43739
A18: or item code = | B18: 59185 | C18: 1800 ULTIMATE BLOOD ORANGE MARGARITA PET | D18: 1.75L | E18: 0 | F18: 15 | G18: 6 | H18: 106.1 | I18: 0 | J18: False | K18: 0 | L18: COCKTAILS | M18: PROXIMO SPIRITS INC | N18: 040002-RNDC-MAGNOLIA | P18: 10811538018958 | Q18: 811538018951 | R18: 43983
A19: or item code = | B19: 59182 | C19: 1800 ULTIMATE MANGO MARGARITA RTD PET | D19: 1.75L | E19: 0 | F19: 7 | G19: 6 | H19: 106.1 | I19: 0 | J19: False | K19: 0 | L19: COCKTAILS | M19: PROXIMO SPIRITS INC | N19: 040002-RNDC-MAGNOLIA | P19: 10811538018927 | Q19: 0811538018920 | R19: 43532
A20: or item code = | B20: 59154 | C20: 1800 ULTIMATE MARGARITA RTD | D20: 1.75L | E20: 192 | F20: 198 | G20: 6 | H20: 106.1 | I20: 0 | J20: False | K20: 0 | L20: COCKTAILS | M20: PROXIMO SPIRITS INC | N20: 040002-RNDC-MAGNOLIA | P20: 10811538019153 | Q20: 0811538019156 | R20: 42370
A21: or item code = | B21: 59161 | C21: 1800 ULTIMATE PEACH MARGARITA PET | D21: 1.75L | E21: 23 | F21: 213 | G21: 6 | H21: 106.1 | I21: 0 | J21: False | K21: 0 | L21: COCKTAILS | M21: PROXIMO SPIRITS INC | N21: 040002-RNDC-MAGNOLIA | Q21: 818844023150 | R21: 42370
A22: or item code = | B22: 59162 | C22: 1800 ULTIMATE PINEAPPLE MAR. | D22: 1.75L | E22: 0 | F22: 249 | G22: 6 | H22: 106.1 | I22: 0 | J22: False | K22: 0 | L22: COCKTAILS | M22: PROXIMO SPIRITS INC | N22: 040002-RNDC-MAGNOLIA | P22: 10811538010396 | Q22: 818844023167 | R22: 42370
A23: or item code = | B23: 59159 | C23: 1800 ULTIMATE RASPBERRY PET | D23: 1.75L | E23: 0 | F23: 59 | G23: 6 | H23: 106.1 | I23: 0 | J23: False | K23: 0 | L23: COCKTAILS | M23: PROXIMO SPIRITS INC | N23: 040002-RNDC-MAGNOLIA | P23: 10811538013816 | Q23: 0811538013819 | R23: 42538
A24: or item code = | B24: 59201 | C24: 1800 ULTIMATE STRAWBERRY MARGARITA RTD | D24: 1.75L | E24: 0 | F24: 96 | G24: 6 | H24: 106.1 | I24: 0 | J24: False | K24: 0 | L24: COCKTAILS | M24: PROXIMO SPIRITS INC | N24: 040002-RNDC-MAGNOLIA | P24: 10818844022778 | Q24: 818844022771 | R24: 44593
A25: or item code = | B25: 59163 | C25: 1800 WATERMELON RTD TEQUILA | D25: 1.75L | E25: 0 | F25: 9 | G25: 6 | H25: 106.1 | I25: 0 | J25: False | K25: 0 | L25: COCKTAILS | M25: PROXIMO SPIRITS INC | N25: 040002-RNDC-MAGNOLIA | Q25: 0811538016445 | R25: 43207
A26: or item code = | B26: 419951 | C26: 19 CRIMES CABERNET SAUVINGON | D26: 750ml | E26: 0 | F26: 23 | G26: 12 | H26: 96.44 | I26: 0 | J26: False | K26: 0 | L26: CABERNET SAUVIGNON | M26: TREASURY WINE ESTATES AMERICAS CO | N26: 040003-RNDC-VINTAGE | P26: 10012354001357 | Q26: 0012354001350 | R26: 42370
A27: or item code = | B27: 671421 | C27: 19 CRIMES CALI ROSE | D27: 750ml | E27: 44 | F27: 35 | G27: 12 | H27: 125.8 | I27: 0 | J27: False | K27: 0 | L27: RED WINE | M27: TREASURY WINE ESTATES AMERICAS CO | N27: 040003-RNDC-VINTAGE | Q27: 012354005006 | R27: 44348
A28: or item code = | B28: 419959 | C28: 19 CRIMES HARD CHARD CHARDONNAY | D28: 750ml | E28: 0 | F28: 19 | G28: 12 | H28: 96.45 | I28: 0 | J28: False | K28: 0 | L28: WHITE WINE | M28: TREASURY WINE ESTATES AMERICAS CO | N28: 040003-RNDC-VINTAGE | P28: 10012354001944 | Q28: 0012354001947 | R28: 43139
A29: or item code = | B29: 490692 | C29: 19 CRIMES MODERN CALI RED | D29: 750ml | E29: 0 | F29: 8 | G29: 12 | H29: 125.8 | I29: 0 | J29: False | K29: 0 | L29: RED WINE | M29: TREASURY WINE ESTATES AMERICAS CO | N29: 040003-RNDC-VINTAGE | P29: 00012354004771 | Q29: 012354004290 | R29: 44136
A30: or item code = | B30: 419952 | C30: 19 CRIMES RED WINE | D30: 750ml | E30: 0 | F30: 4 | G30: 12 | H30: 96.45 | I30: 0 | J30: False | K30: 0 | L30: RED WINE | M30: TREASURY WINE ESTATES AMERICAS CO | N30: 040003-RNDC-VINTAGE | P30: 10012354000992 | Q30: 0012354000995 | R30: 42370
A31: or item code = | B31: 419955 | C31: 19 CRIMES THE BANISHED RED WINE | D31: 750ml | E31: 0 | F31: 51 | G31: 12 | H31: 96.45 | I31: 0 | J31: False | K31: 0 | L31: RED WINE | M31: TREASURY WINE ESTATES AMERICAS CO | N31: 040003-RNDC-VINTAGE | P31: 10012354001685 | Q31: 0012354001688 | R31: 42808
A32: or item code = | B32: 419973 | C32: 19 CRIMES THE PUNISHMENT PINOT NOIR | D32: 750ml | E32: 0 | F32: 23 | G32: 12 | H32: 96.45 | I32: 0 | J32: False | K32: 0 | L32: RED WINE | M32: TREASURY WINE ESTATES AMERICAS CO | N32: 040003-RNDC-VINTAGE | P32: 10089819721440 | Q32: 089819721443 | R32: 43360
A33: or item code = | B33: 419961 | C33: 19 CRIMES THE UPRISING RED WINE | D33: 750ml | E33: 25 | F33: 73 | G33: 12 | H33: 96.45 | I33: 0 | J33: False | K33: 0 | L33: RED WINE | M33: TREASURY WINE ESTATES AMERICAS CO | N33: 040003-RNDC-VINTAGE | Q33: 0012354001930 | R33: 43139
A34: or item code = | B34: 41943 | C34: 360 GEORGIA PEACH FLAVORED VODKA | D34: 750ml | E34: 1 | F34: 36 | G34: 12 | H34: 125.92 | I34: 0 | J34: False | K34: 0 | L34: VODKA | M34: MCCORMICK DISTILLING COMPANY | N34: 040002-RNDC-MAGNOLIA | P34: 10085592142458 | Q34: 0085592142451 | R34: 42370
A35: or item code = | B35: 84170 | C35: 99 BRAND BANANAS | D35: 750ml | E35: 8 | F35: 26 | G35: 12 | H35: 150.37 | I35: 0 | J35: False | K35: 0 | L35: LIQUEURS AND CORDIALS | M35: SAZERAC COMPANY | N35: 040002-RNDC-MAGNOLIA | P35: 10089000990761 | Q35: 0080660620053 | R35: 42370
A36: or item code = | B36: 84172 | C36: 99 BRAND BANANAS SCHNAPPS | D36: 50ml | E36: 37 | F36: 81 | G36: 120 | H36: 80 | I36: 0 | J36: False | K36: 0 | L36: LIQUEURS AND CORDIALS | M36: SAZERAC COMPANY | N36: 040002-RNDC-MAGNOLIA | P36: 00080660620091 | Q36: 0080660620992 | R36: 42474
A37: or item code = | B37: 84222 | C37: 99 BRAND BLUE RASPBERRIES | D37: 50ml | E37: 157 | F37: 60 | G37: 120 | H37: 80 | I37: 0 | J37: False | K37: 0 | L37: LIQUEURS AND CORDIALS | M37: SAZERAC COMPANY | N37: 040002-RNDC-MAGNOLIA | P37: 10088004039667 | Q37: 0088004039660 | R37: 44228
A38: or item code = | B38: 84191 | C38: 99 BRAND BUTTERSCOTCH SCHNAPPS | D38: 50ml | E38: 75 | F38: 44 | G38: 120 | H38: 80 | I38: 0 | J38: False | K38: 0 | L38: LIQUEURS AND CORDIALS | M38: SAZERAC COMPANY | N38: 040002-RNDC-MAGNOLIA | P38: 10080660010110 | Q38: 0080660010113 | R38: 44044
A39: or item code = | B39: 84142 | C39: 99 BRAND PEACHES | D39: 50ml | E39: 72 | F39: 55 | G39: 120 | H39: 80 | I39: 0 | J39: False | K39: 0 | L39: LIQUEURS AND CORDIALS | M39: SAZERAC COMPANY | N39: 040002-RNDC-MAGNOLIA | P39: 10089000990617 | Q39: 089000990610 | R39: 42370
A40: or item code = | B40: 87054 | C40: 99 BRAND PEANUT BUTTER WHISKEY | D40: 50ml | E40: 34 | F40: 22 | G40: 120 | H40: 80 | I40: 0 | J40: False | K40: 0 | L40: WHISKEY - BLENDED | M40: SAZERAC COMPANY | N40: 040002-RNDC-MAGNOLIA | P40: 10088004038554 | Q40: 00088004038557 | R40: 44044
A41: or item code = | B41: 84226 | C41: 99 BRAND STRAWBERRIES | D41: 50ml | E41: 191 | F41: 61 | G41: 120 | H41: 80 | I41: 0 | J41: False | K41: 0 | L41: LIQUEURS AND CORDIALS | M41: SAZERAC COMPANY | N41: 040002-RNDC-MAGNOLIA | P41: 10088004039650 | Q41: 0088004039653 | R41: 44166
A42: or item code = | B42: 4000 | C42: ABERFELDY 12 YR SINGLE MALT SCOTCH WHISKEY | D42: 750ml | E42: 0 | F42: 9 | G42: 6 | H42: 212.25 | I42: 0 | J42: False | K42: 0 | L42: WHISKY - SCOTCH | M42: BACARDI USA INC | N42: 040010-SOUTHERN GLAZERS WINE AND SPIRITS OF MISSISSIPPI LLC | Q42: 0080480220006 | R42: 42370
...

Sheet Sheet1
A1: Item # | B1: Name | C1: Size | D1: Reserved Quantity | E1: Order | F1: Date | G1: Note
A2: 35418 | B2: BURNETT'S VODKA 80 PROOF | C2: =VLOOKUP(A2,SizeData!A$2:B$3839,2,FALSE) | D2: 20 | E2: R1870929 | F2: 44879
A3: 93566 | B3: TAYLOR N Y PORT | C3: =VLOOKUP(A3,SizeData!A$2:B$3839,2,FALSE) | D3: 20 | E3: R1870929 | F3: 44879
A4: 53214 | B4: PAUL MASSON GRANDE AMBER BRANDY | C4: =VLOOKUP(A4,SizeData!A$2:B$3839,2,FALSE) | D4: 20 | E4: R1870929 | F4: 44879
A5: 63319 | B5: ON THE ROCKS EFFEN COSMOPOLITAN | C5: =VLOOKUP(A5,SizeData!A$2:B$3839,2,FALSE) | D5: 60 | E5: R1870929 | F5: 44879
A6: 63321 | B6: ON THE ROCKS HORINITOS MARGARITA | C6: =VLOOKUP(A6,SizeData!A$2:B$3839,2,FALSE) | D6: 30 | E6: R1870929 | F6: 44879

Sheet Special Order 2021
A1: Retail Order Id | B1: Created | C1: Item Code | D1: Name | E1: Units | F1: Retailer Case Cost | G1: Quantity | H1: Requested | I1: Reserved | J1: Filled | K1: Order Status
A2: R1019736A | B2: 44266 | C2: 59192 | D2: 1800 BLACK CHERRY ULTIMATE MARGARITA | E2: 6 | F2: 106.81 | G2: 1 | H2: 1 | I2: 1 | J2: 1 | K2: Shipped
A3: R1128492 | B3: 44351 | C3: 89695 | D3: 1800 NUEVO MILENIO | E3: 3 | F3: 507.5 | G3: 1 | H3: 1 | I3: 1 | J3: 1 | K3: Shipped
A4: R1004582 | B4: 44229 | C4: 671421 | D4: 19 CRIMES CALI ROSE | E4: 12 | F4: 106.56 | G4: 15 | H4: 15 | I4: 15 | J4: 15 | K4: Shipped
A5: R1264384 | B5: 44481 | C5: 81124 | D5: 99 BRAND PEPPERMINT | E5: 120 | F5: 79.2 | G5: 1 | H5: 1 | I5: 1 | J5: 1 | K5: Shipped
A6: R990101A | B6: 44224 | C6: 36768 | D6: ABSOLUT GRAPEFRUIT FLAVORED VODKA | E6: 24 | F6: 119.82 | G6: 1 | H6: 1 | I6: 1 | J6: 1 | K6: Shipped
A7: R1047542C | B7: 44314 | C7: 36768 | D7: ABSOLUT GRAPEFRUIT FLAVORED VODKA | E7: 24 | F7: 119.82 | G7: 1 | H7: 1 | I7: 1 | J7: 1 | K7: Shipped
A8: R990101A | B8: 44224 | C8: 64013 | D8: ABSOLUT JUICE STRAWBERRY EDITION | E8: 24 | F8: 119.82 | G8: 1 | H8: 1 | I8: 1 | J8: 1 | K8: Shipped
A9: R1047542A | B9: 44302 | C9: 64013 | D9: ABSOLUT JUICE STRAWBERRY EDITION | E9: 24 | F9: 119.82 | G9: 2 | H9: 2 | I9: 2 | J9: 2 | K9: Shipped
A10: R990101A | B10: 44224 | C10: 36685 | D10: ABSOLUT LIME FLAVORED VODKA | E10: 24 | F10: 119.82 | G10: 1 | H10: 1 | I10: 1 | J10: 1 | K10: Shipped
A11: R1047542 | B11: 44260 | C11: 36685 | D11: ABSOLUT LIME FLAVORED VODKA | E11: 24 | F11: 119.82 | G11: 1 | H11: 1 | I11: 1 | J11: 1 | K11: Shipped
A12: R1323780 | B12: 44512 | C12: 87025 | D12: ADICTIVO PLATA TEQUILA | E12: 6 | F12: 230.74 | G12: 1 | H12: 1 | I12: 1 | J12: 1 | K12: Shipped
A13: R1330163 | B13: 44512 | C13: 47541 | D13: ANSAC BLACK KNIGHT SELECTION COGNAC | E13: 6 | F13: 138.43 | G13: 2 | H13: 2 | I13: 2 | J13: 2 | K13: Shipped
... A421: R1337993 | B421: 44529 | C421: 22257 | D421: WOODFORD RESERVE STRAIGHT WHEAT | E421: 6 | F421: 172.75 | G421: 4 | H421: 4 | I421: 4 | J421: 4 | K421: Shipped
E422: 7474 | F422: 86794.09 | G422: 1108 | H422: 1109 | I422: 1108 | J422: 1074

Sheet Sheet2
D1: =SUM(D2:D9060)
B2: Name | C2: Size | D2: Reserved Quantity
A3: 87509 | B3: 1800 SILVER TEQUILA | C3: #N/A | D3: 10
A4: 59154 | B4: 1800 ULTIMATE MARGARITA RTD | C4: #N/A | D4: 1
A5: 59161 | B5: 1800 ULTIMATE PEACH MARGARITA | C5: #N/A | D5: 5
A6: 59201 | B6: 1800 ULTIMATE STRAWBERRY MARGARITA RTD LTO | C6: #N/A | D6: 25
A7: 419961 | B7: 19 CRIMES THE UPRISING RED WINE | C7: #N/A | D7: 1
A8: 100959 | B8: 99 PEANUT BUTTER WHISKEY COUNTER UNIT | C8: #N/A | D8: 1
A9: 34003 | B9: ABSOLUT 80 VODKA | C9: #N/A | D9: 2
A10: 43028 | B10: ADMIRAL NELSON'S SPICED RUM | C10: #N/A | D10: 3
A11: 768676 | B11: ANDRE CHAMPAGNE MOSCATO | C11: #N/A | D11: 2
A12: 768692 | B12: ANDRE CHAMPAGNE STRAWBERRY MOSCATO | C12: #N/A | D12: 2
A13: 43126 | B13: BACARDI LIGHT RUM | C13: #N/A | D13: 2
A14: 768950 | B14: BALLATORE SPUMANTE | C14: #N/A | D14: 1
... A39: 88833 | B39: CASAMIGOS ANEJO TEQUILA 100% AGAVE | C39: #N/A | D39: 5
A40: 87280 | B40: CASAMIGOS BLANCO TEQUILA 100% AGAVE | C40: =VLOOKUP(A40,SizeData!#REF!,2,FALSE) | D40: 5
A41: 87280 | B41: CASAMIGOS BLANCO TEQUILA 100% AGAVE | C41: #N/A | D41: 5
A42: 89177 | B42: CASAMIGOS REPOSADO TEQUILA 100% AGAVE | C42: #N/A | D42: 5
A43: 57120 | B43: CHI CHI'S LONG ISLAND ICED TEA | C43: #N/A | D43: 1
A44: 57181 | B44: CHI CHI'S PINEAPPLE MARGARITA | C44: #N/A | D44: 1
A45: 57148 | B45: CHI-CHI'S MARGARITA | C45: #N/A | D45: 2
A46: 57144 | B46: CHI-CHI'S WHITE RUSSIAN | C46: #N/A | D46: 1
A47: 64514 | B47: CIROC APPLE FLAVORED VODKA SPECIALTY | C47: #N/A | D47: 1
A48: 64744 | B48: CIROC COCONUT FLAVORED VODKA SPECIALTY | C48: #N/A | D48: 1
A49: 64714 | B49: CIROC PEACH FLAVORED VODKA SPECIALTY | C49: #N/A | D49: 1
A50: 64575 | B50: CIROC PINEAPPLE FLAVORED VODKA SPECIALTY | C50: #N/A | D50: 1
A51: 64572 | B51: CIROC PINEAPPLE FLAVORED VODKA SPECIALTY | C51: #N/A | D51: 1
A52: 34201 | B52: CIROC SNAP FROST VODKA | C52: #N/A | D52: 1
A53: 51107 | B53: CIROC VS FRENCH BRANDY | C53: #N/A | D53: 1
A54: 47786 | B54: COURVOISIER V S COGNAC | C54: =VLOOKUP(A54,SizeData!#REF!,2,FALSE) | D54: 20
A55: 10838 | B55: CROWN ROYAL BLACK | C55: #N/A | D55: 10
A56: 10836 | B56: CROWN ROYAL BLACK | C56: #N/A | D56: 6
A57: 10807 | B57: CROWN ROYAL REGAL APPLE FLAVORED WHISKEY | C57: #N/A | D57: 5
A58: 10809 | B58: CROWN ROYAL REGAL APPLE FLAVORED WHISKEY | C58: #N/A | D58: 1
A59: 35648 | B59: CROWN RUSSE VODKA | C59: #N/A | D59: 1
A60: 58838 | B60: CUERVO LIME MARGARITA / 20PF | C60: #N/A | D60: 2
A61: 58868 | B61: CUERVO STRAWBERRY MARGARITA / 20PF | C61: #N/A | D61: 2
A62: 86110 | B62: DEKUYPER TRIPLE SEC | C62: #N/A | D62: 1
A63: 89154 | B63: DON JULIO REPOSADO TEQUILA GOLD | C63: =VLOOKUP(A63,SizeData!#REF!,2,FALSE) | D63: 1
A64: 462522 | B64: DUPLIN CAROLINA RED | C64: #N/A | D64: 2
...

Sheet Lottery_3_7_2022
B1: =TODAY() | C1: Total | D1: =SUM(D3:D3477)
A2: Item # | B2: Name | C2: Size | D2: Reserved Quantity | E2: Order | F2: Date | G2: Note
A3: 87509 | B3: 1800 SILVER TEQUILA | C3: #N/A | D3: 10 | E3: R1483559 | F3: 44622
A4: 59154 | B4: 1800 ULTIMATE MARGARITA RTD | C4: #N/A | D4: 1 | E4: R1497382 | F4: 44627
A5: 59161 | B5: 1800 ULTIMATE PEACH MARGARITA | C5: #N/A | D5: 5 | E5: R1493246 | F5: 44623
A6: 59201 | B6: 1800 ULTIMATE STRAWBERRY MARGARITA RTD LTO | C6: #N/A | D6: 25 | E6: R1473430 | F6: 44615
A7: 419961 | B7: 19 CRIMES THE UPRISING RED WINE | C7: #N/A | D7: 1 | E7: R1496401 | F7: 44621
A8: 100959 | B8: 99 PEANUT BUTTER WHISKEY COUNTER UNIT | C8: #N/A | D8: 1 | E8: R1469832 | F8: 44615
A9: 34003 | B9: ABSOLUT 80 VODKA | C9: #N/A | D9: 2 | E9: R1496619 | F9: 44621
A10: 43028 | B10: ADMIRAL NELSON'S SPICED RUM | C10: #N/A | D10: 3 | E10: R1486326 | F10: 44616
A11: 768676 | B11: ANDRE CHAMPAGNE MOSCATO | C11: #N/A | D11: 2 | E11: R1496401 | F11: 44621
A12: 768692 | B12: ANDRE CHAMPAGNE STRAWBERRY MOSCATO | C12: #N/A | D12: 2 | E12: R1496401 | F12: 44621
A13: 768950 | B13: BALLATORE SPUMANTE | C13: #N/A | D13: 1 | E13: R1488872 | F13: 44627
A14: 16652 | B14: BARDSTOWN BOURBON COMPANY FUSION SERIES | C14: #N/A | D14: 2 | E14: R1501158 | F14: 44627
... A174: 429975 | B174: YELLOW TAIL MERLOT | C174: #N/A | D174: 3 | E174: R1493246 | F174: 44623
